Workbook

Sheet Panduan
A1: APZACCT — PANDUAN ASAS SISTEM PERAKAUNAN KOPERASI (BUKAN FORMAT SKM EASY COOP)
A3: Apa buku kerja ini
A4: Asas (foundation) untuk sistem baharu — struktur sendiri, ikut prinsip perakaunan berganda standard. Format penyata rasmi (KKK/UR/AT) kekal ikut bentuk SKM harapkan; cara data dimasukkan yang berubah sepenuhnya.
A6: Cara helaian berkait
A7: Akaun -> Transaksi + Baris_Transaksi -> Imbangan_Duga (auto SUMIF) -> UR dan KKK (auto daripada Imbangan_Duga) -> AT (auto daripada UR + Baris_Transaksi, kaedah tidak langsung). Tiada nombor ditaip terus ke UR/KKK/AT — semua formula.
A9: PRINSIP PENTING: Akaun mula LEAN, bukan penuh macam EASY COOP
A10: Percubaan awal migrasi semua 97 kategori sebenar daripada AKAUN_INDEX lama telah DITARIK BALIK. Sebab: kebanyakan kategori itu (Jualan-Akuakultur, Jualan-Pembangunan Hartanah, dll.) cuma relevan untuk koperasi yang benar-benar buat perniagaan itu — bina lebih awal daripada perlu bermakna akaun kosong bertimbun, sama macam masalah asal EASY COOP. Akaun sekarang cuma 29 akaun teras (tunai, bank, modal syer, rizab, perbelanjaan pentadbiran wajib, dll.) yang hampir semua koperasi perlukan tanpa mengira jenis perniagaan. Akaun khusus perniagaan (pinjaman ahli, jualan runcit, sewaan, dll.) TIDAK dibina sehingga disahkan koperasi ini benar-benar buat aktiviti itu.
A12: SAHKAN sebelum diguna sebenar
A13: Akaun 2030 "Akaun Deposit Koperasi": fail rujukan sebenar (Koperasi Ikram Miri) letak ADK di bawah ASET, bukan Liabiliti — anggapan asal mungkin salah arah. Akaun 4020 "Faedah / Hibah Bank": nama neutral buat masa ini, tunggu pengesahan sama ada koperasi ini konvensional (Faedah) atau patuh Syariah (Hibah).
A15: Baki Bersih (Imbangan_Duga lajur H)
A16: Lajur bertanda: positif = ikut baki normal akaun, negatif = kedudukan kontra. UR/KKK rujuk lajur ini supaya akaun kontra (jika ditambah kelak) automatik tolak daripada jumlah kumpulannya, bukan tambah.
A18: Apa yang BELUM dibina
... A221: Baki_Pembukaan (helaian baharu) + APZacct_BakiPembukaan.gs: cara sebenar masukkan baki teraudit tahun lepas - satu transaksi seimbang, dan secara automatik kemaskini Tetapan!C18 supaya pengecualian baki pembukaan di AT betul (dulu terikat keras kepada "CONTOH-0000"). APZacct_LogPerubahan.gs: ubah data yang sudah dipos (jumlah, kod akaun, jenis akaun) kini perlukan sebab, direkod dalam helaian Log_Perubahan - bukan kunci keras, tapi tiada perubahan senyap. Daftar_Aset_Tetap (helaian baharu): daftar aset individu, sokong Garis Lurus dan Baki Berkurangan, disahkan tepat kepada sen untuk caj tahunan (angka terkumpul mungkin beza sikit disebabkan cara YEARFRAC kira hari - lihat nota dalam helaian). Ditambah juga akaun kontra 1045 (Susut Nilai Terkumpul) dan 1095 (Peruntukan Hutang Ragu, wajib GP23 untuk pinjaman). Wizard kini kesan perkataan seperti "tahunan"/"insurans"/"sewa" dan tawar pilihan tukar ke akaun Prabayar/Terakru sebelum simpan - PENTING: PENTING semua onOpen() diselaraskan ke SATU fail (APZacct_Menu.gs) - fail lain sebelum ini masing-masing ada onOpen sendiri, bermakna cuma SATU menu yang muncul walaupun semua fail ditampal. Ini dibetulkan.

Sheet Tetapan
A1: TETAPAN (SETTINGS)
A2: Lajur kuning (Nilai Digunakan) adalah SATU-SATUNYA lajur untuk diedit. Jangan sentuh helaian lain untuk tukar nilai ini.
A4: Tetapan | B4: Nilai Lalai (rujukan) | C4: Nilai Digunakan (edit di sini) | D4: Penerangan
A5: Nama Koperasi | B5: Koperasi Contoh Berhad | C5: Koperasi Contoh Berhad | D5: Nama penuh untuk kepala setiap penyata rasmi
A6: No. Pendaftaran SKM | D6: Nombor pendaftaran rasmi dengan Suruhanjaya Koperasi Malaysia
A7: Bulan Mula Tahun Kewangan | B7: Januari | C7: Januari | D7: Bulan permulaan tahun kewangan koperasi (cth: Januari, April)
A8: Simbol Mata Wang | B8: RM | C8: RM | D8: Digunakan pada semua format nombor wang
A9: Bahasa Utama Aplikasi Web | B9: English | C9: English | D9: Bahasa lalai antara muka wizard; istilah perakaunan tetap ada tooltip BM (lihat Kamus_Istilah)
A10: Kod Akaun Seterusnya — Aset | B10: 1150 | C10: 1150 | D10: Kod kosong seterusnya dalam julat 1000-1999
A11: Kod Akaun Seterusnya — Liabiliti | B11: 2080 | C11: 2080 | D11: Kod kosong seterusnya dalam julat 2000-2999
A12: Kod Akaun Seterusnya — Ekuiti | B12: 3070 | C12: 3070 | D12: Kod kosong seterusnya dalam julat 3000-3999
A13: Kod Akaun Seterusnya — Hasil | B13: 4230 | C13: 4230 | D13: Kod kosong seterusnya dalam julat 4000-4999
A14: Kod Akaun Seterusnya — Perbelanjaan | B14: 5430 | C14: 5430 | D14: Kod kosong seterusnya dalam julat 5000-5999
A15: Kadar Rizab Statutori (%) | B15: 25 | C15: 25 | D15: s.57(1) Akta Koperasi 1993: 25% selagi Rizab < 50% Modal Syer+Yuran, jatuh ke 15% selepas itu - semak sendiri kedudukan semasa
A16: Kadar KWA Pendidikan Koperasi (%) | B16: 2 | C16: 2 | D16: Ikut arahan SKM semasa - sahkan kadar terkini
A17: Kadar KWA Pembangunan Koperasi (%) | B17: 1 | C17: 1 | D17: Ikut arahan SKM semasa - sahkan kadar terkini
A18: ID Transaksi Baki Pembukaan | B18: CONTOH-0000 | C18: CONTOH-0000 | D18: AT rujuk sel ini untuk kecualikan baki pembukaan daripada aliran tunai tempoh semasa. Skrip Tambah_Baki_Pembukaan.gs kemaskini ini automatik.
A21: Tarikh Kunci Tempoh Kewangan | D21: Tarikh terakhir yang sudah dibentangkan kepada Lembaga - baris bertarikh pada atau sebelum ini akan ditanda amaran dalam Import Penyata Bank & Rekonsiliasi Bank. Kosongkan untuk nyahaktifkan amaran ini.
A22: Tahun Kewangan Susut Nilai Terakhir Dipos | D22: Diisi automatik oleh Pos Susut Nilai Aset selepas pos berjaya - jangan edit terus.

Sheet Kamus_Istilah
A1: KAMUS ISTILAH (BILINGUAL GLOSSARY)
A2: English = bahasa utama aplikasi web. Bahasa Malaysia = tooltip. Helaian ini boleh dibaca terus oleh wizard nanti.
A4: Istilah (English) | B4: Istilah (Bahasa Malaysia) | C4: Penerangan Ringkas
A5: Chart of Accounts | B5: Carta Akaun | C5: Senarai semua akaun yang koperasi guna, dengan jenis masing-masing
A6: Account | B6: Akaun | C6: Satu kategori tempat wang direkod, cth. Bank, Jualan, Perbelanjaan Pejabat
A7: Transaction | B7: Transaksi | C7: Satu peristiwa kewangan, cth. satu resit atau satu PV
A8: Debit | B8: Debit | C8: Sisi kiri catatan berganda; menambah Aset/Perbelanjaan, mengurang Liabiliti/Ekuiti/Hasil
A9: Credit | B9: Kredit | C9: Sisi kanan catatan berganda; menambah Liabiliti/Ekuiti/Hasil, mengurang Aset/Perbelanjaan
A10: Trial Balance | B10: Imbangan Duga | C10: Senarai semua baki akaun; jumlah Debit mesti sama dengan jumlah Kredit
A11: Balance Sheet | B11: Kunci Kira-Kira (KKK) | C11: Kedudukan Aset, Liabiliti dan Ekuiti pada satu tarikh
A12: Income Statement | B12: Akaun Untung Rugi (UR) | C12: Hasil tolak Perbelanjaan bagi satu tempoh
A13: Cash Flow Statement | B13: Penyata Aliran Tunai (AT) | C13: Pergerakan tunai masuk dan keluar bagi satu tempoh
A14: Opening Balance | B14: Baki Awal / Pembukaan | C14: Baki setiap akaun pada permulaan tahun kewangan baharu
A15: Member Equity | B15: Ekuiti Ahli | C15: Modal syer, rizab dan lebihan terkumpul kepunyaan ahli koperasi
... A53: Contra Entry / Transfer | B53: Kontra / Pindahan | C53: Pindahan antara dua akaun wang sendiri, cth. petty ke bank - bukan hasil atau perbelanjaan

Sheet Akaun
A1: CARTA AKAUN (CHART OF ACCOUNTS)
A2: Setiap baris ialah SATU akaun. Lajur I = Semasa/Bukan Semasa (Aset & Liabiliti sahaja, ikut format KKK rasmi).
A4: Kod Akaun | B4: Nama Akaun (EN) | C4: Nama Akaun (BM) | D4: Jenis | E4: Baki Normal | F4: Kumpulan Aliran Tunai | G4: Status | H4: Nota | I4: Semasa/Bukan Semasa
A5: 1010 | B5: Cash in hand | C5: Wang Di Tangan | D5: Aset | E5: =IF(OR(D5="Aset",D5="Perbelanjaan"),"Debit","Kredit") | F5: Tidak Berkaitan | G5: Aktif | I5: Semasa
A6: 1020 | B6: Bank | C6: Bank | D6: Aset | E6: =IF(OR(D6="Aset",D6="Perbelanjaan"),"Debit","Kredit") | F6: Tidak Berkaitan | G6: Aktif | I6: Semasa
A7: 1030 | B7: Fixed Deposit | C7: Deposit Tetap | D7: Aset | E7: =IF(OR(D7="Aset",D7="Perbelanjaan"),"Debit","Kredit") | F7: Pelaburan | G7: Aktif | I7: Bukan Semasa
A8: 1040 | B8: Fixed Assets (general) | C8: Aset Tetap | D8: Aset | E8: =IF(OR(D8="Aset",D8="Perbelanjaan"),"Debit","Kredit") | F8: Pelaburan | G8: Aktif | H8: Pecahkan Tanah/Bangunan/Kenderaan bila disahkan pemilikan sebenar | I8: Bukan Semasa
A9: 1050 | B9: Cooperative Deposit Account | C9: Akaun Deposit Koperasi | D9: Aset | E9: =IF(OR(D9="Aset",D9="Perbelanjaan"),"Debit","Kredit") | F9: Pelaburan | G9: Aktif | H9: DIBETULKAN: Aset Bukan Semasa ikut format KKK rasmi (bukan Liabiliti seperti anggapan asal) | I9: Bukan Semasa
A10: 1060 | B10: Retail Inventory | C10: Inventori Runcit | D10: Aset | E10: =IF(OR(D10="Aset",D10="Perbelanjaan"),"Debit","Kredit") | F10: Operasi | G10: Aktif | I10: Semasa
A11: 1070 | B11: Poultry & Slaughter Product Inventory | C11: Inventori Ayam & Produk Sembelihan | D11: Aset | E11: =IF(OR(D11="Aset",D11="Perbelanjaan"),"Debit","Kredit") | F11: Operasi | G11: Aktif | I11: Semasa
A12: 2010 | B12: Various Creditors | C12: Pelbagai Pemiutang | D12: Liabiliti | E12: =IF(OR(D12="Aset",D12="Perbelanjaan"),"Debit","Kredit") | F12: Operasi | G12: Aktif | I12: Semasa
A13: 2020 | B13: Dividend Declared | C13: Dividen Diisytiharkan | D13: Liabiliti | E13: =IF(OR(D13="Aset",D13="Perbelanjaan"),"Debit","Kredit") | F13: Berkanun | G13: Aktif | I13: Semasa
A14: 3010 | B14: Member Share Capital | C14: Modal Syer Ahli | D14: Ekuiti | E14: =IF(OR(D14="Aset",D14="Perbelanjaan"),"Debit","Kredit") | F14: Pembiayaan | G14: Aktif
A15: 3020 | B15: Statutory Reserve | C15: Rizab Statutori | D15: Ekuiti | E15: =IF(OR(D15="Aset",D15="Perbelanjaan"),"Debit","Kredit") | F15: Tidak Berkaitan | G15: Aktif | H15: Wajib di bawah Akta Koperasi 1993
A16: 3030 | B16: Accumulated Surplus | C16: Lebihan Terkumpul | D16: Ekuiti | E16: =IF(OR(D16="Aset",D16="Perbelanjaan"),"Debit","Kredit") | F16: Tidak Berkaitan | G16: Aktif
A17: 4010 | B17: Entrance Fee | C17: Fi Masuk | D17: Hasil | E17: =IF(OR(D17="Aset",D17="Perbelanjaan"),"Debit","Kredit") | F17: Operasi | G17: Aktif
A18: 4020 | B18: Bank Interest (conventional) | C18: Faedah Bank | D18: Hasil | E18: =IF(OR(D18="Aset",D18="Perbelanjaan"),"Debit","Kredit") | F18: Operasi | G18: Aktif
A19: 4030 | B19: Bank Hibah (Islamic) | C19: Hibah Bank | D19: Hasil | E19: =IF(OR(D19="Aset",D19="Perbelanjaan"),"Debit","Kredit") | F19: Operasi | G19: Aktif
A20: 4040 | B20: Retail Sales | C20: Jualan Runcit | D20: Hasil | E20: =IF(OR(D20="Aset",D20="Perbelanjaan"),"Debit","Kredit") | F20: Operasi | G20: Aktif
A21: 4050 | B21: Service Income | C21: Pendapatan Perkhidmatan | D21: Hasil | E21: =IF(OR(D21="Aset",D21="Perbelanjaan"),"Debit","Kredit") | F21: Operasi | G21: Aktif
A22: 4060 | B22: Training & Course Income | C22: Pendapatan Latihan & Kursus | D22: Hasil | E22: =IF(OR(D22="Aset",D22="Perbelanjaan"),"Debit","Kredit") | F22: Operasi | G22: Aktif
A23: 4070 | B23: F&B Sales | C23: Jualan Makanan & Minuman | D23: Hasil | E23: =IF(OR(D23="Aset",D23="Perbelanjaan"),"Debit","Kredit") | F23: Operasi | G23: Aktif
A24: 4080 | B24: Halal Poultry & Slaughter Product Sales | C24: Jualan Ayam & Produk Sembelihan | D24: Hasil | E24: =IF(OR(D24="Aset",D24="Perbelanjaan"),"Debit","Kredit") | F24: Operasi | G24: Aktif
A25: 5010 | B25: Office Expenses | C25: Perbelanjaan Pejabat | D25: Perbelanjaan | E25: =IF(OR(D25="Aset",D25="Perbelanjaan"),"Debit","Kredit") | F25: Operasi | G25: Aktif
A26: 5020 | B26: Board Expenses | C26: Perbelanjaan Lembaga | D26: Perbelanjaan | E26: =IF(OR(D26="Aset",D26="Perbelanjaan"),"Debit","Kredit") | F26: Operasi | G26: Aktif
A27: 5030 | B27: Salaries and Allowances | C27: Gaji dan Elaun | D27: Perbelanjaan | E27: =IF(OR(D27="Aset",D27="Perbelanjaan"),"Debit","Kredit") | F27: Operasi | G27: Aktif
... A33: 5090 | B33: AGM Expenses — Special/EGM | C33: Perbelanjaan Mesyuarat Agung Khas | D33: Perbelanjaan | E33: =IF(OR(D33="Aset",D33="Perbelanjaan"),"Debit","Kredit") | F33: Operasi | G33: Aktif
A34: 5100 | B34: Board Honorarium | C34: Honorarium ALK | D34: Perbelanjaan | E34: =IF(OR(D34="Aset",D34="Perbelanjaan"),"Debit","Kredit") | F34: Operasi | G34: Tidak Aktif | H34: DIPINDAH ke APK sebagai pembahagian keuntungan, bukan perbelanjaan operasi - lihat akaun liabiliti gantian
A35: 5110 | B35: Income Tax | C35: Cukai Pendapatan | D35: Perbelanjaan | E35: =IF(OR(D35="Aset",D35="Perbelanjaan"),"Debit","Kredit") | F35: Operasi | G35: Tidak Aktif | H35: DIPINDAH ke APK sebagai pembahagian keuntungan, bukan perbelanjaan operasi - lihat akaun liabiliti gantian
A36: 5120 | B36: Zakat | C36: Zakat | D36: Perbelanjaan | E36: =IF(OR(D36="Aset",D36="Perbelanjaan"),"Debit","Kredit") | F36: Operasi | G36: Tidak Aktif | H36: DIPINDAH ke APK sebagai pembahagian keuntungan, bukan perbelanjaan operasi - lihat akaun liabiliti gantian
A37: 5130 | B37: Cooperative Education Fund | C37: Bayaran KWA Pendidikan Koperasi | D37: Perbelanjaan | E37: =IF(OR(D37="Aset",D37="Perbelanjaan"),"Debit","Kredit") | F37: Operasi | G37: Tidak Aktif | H37: DIPINDAH ke APK sebagai pembahagian keuntungan, bukan perbelanjaan operasi - lihat akaun liabiliti gantian
A38: 5140 | B38: Cooperative Development Fund | C38: Bayaran KWA Pembangunan Koperasi | D38: Perbelanjaan | E38: =IF(OR(D38="Aset",D38="Perbelanjaan"),"Debit","Kredit") | F38: Operasi | G38: Tidak Aktif | H38: DIPINDAH ke APK sebagai pembahagian keuntungan, bukan perbelanjaan operasi - lihat akaun liabiliti gantian
A39: 5150 | B39: Internet and Telephone | C39: Internet dan Telefon | D39: Perbelanjaan | E39: =IF(OR(D39="Aset",D39="Perbelanjaan"),"Debit","Kredit") | F39: Operasi | G39: Aktif
A40: 5160 | B40: Depreciation | C40: Susut Nilai Aset | D40: Perbelanjaan | E40: =IF(OR(D40="Aset",D40="Perbelanjaan"),"Debit","Kredit") | F40: Operasi | G40: Aktif
A41: 5170 | B41: Miscellaneous Expenses | C41: Pelbagai Perbelanjaan | D41: Perbelanjaan | E41: =IF(OR(D41="Aset",D41="Perbelanjaan"),"Debit","Kredit") | F41: Operasi | G41: Aktif | H41: Tangkapan am
A42: 5180 | B42: Retail Purchases (COGS) | C42: Belian Runcit | D42: Perbelanjaan | E42: =IF(OR(D42="Aset",D42="Perbelanjaan"),"Debit","Kredit") | F42: Operasi | G42: Aktif
A43: 5190 | B43: Training & Course Costs | C43: Kos Latihan & Kursus | D43: Perbelanjaan | E43: =IF(OR(D43="Aset",D43="Perbelanjaan"),"Debit","Kredit") | F43: Operasi | G43: Aktif
A44: 5200 | B44: F&B Raw Material Cost | C44: Kos Bahan Mentah F&B | D44: Perbelanjaan | E44: =IF(OR(D44="Aset",D44="Perbelanjaan"),"Debit","Kredit") | F44: Operasi | G44: Aktif
A45: 5210 | B45: Live Chicken Purchases | C45: Belian Ayam Hidup | D45: Perbelanjaan | E45: =IF(OR(D45="Aset",D45="Perbelanjaan"),"Debit","Kredit") | F45: Operasi | G45: Aktif
A46: 5220 | B46: Slaughtering & Processing Cost | C46: Kos Sembelihan & Pemprosesan | D46: Perbelanjaan | E46: =IF(OR(D46="Aset",D46="Perbelanjaan"),"Debit","Kredit") | F46: Operasi | G46: Aktif
...

Sheet Baki_Pembukaan
A1: BAKI PEMBUKAAN (OPENING BALANCES)
A2: Guna angka daripada penyata kewangan TERAUDIT tahun lepas SAHAJA. Hanya untuk akaun Aset/Liabiliti/Ekuiti - Hasil dan Perbelanjaan tidak patut ada baki pembukaan (ia bermula sifar setiap tahun kewangan baharu). Isi Kod Akaun dan SATU sahaja daripada Debit/Kredit setiap baris ikut baki normal akaun itu, kemudian jalankan menu APZacct > Pos Baki Pembukaan.
A4: Kod Akaun | B4: Nama Akaun (auto) | C4: Jenis (auto) | D4: Debit | E4: Kredit | F4: Status
B5: {=IFERROR(INDEX(Akaun!$C$5:$C$150,MATCH(A5,Akaun!$A$5:$A$150,0)),"")} | C5: {=IFERROR(INDEX(Akaun!$D$5:$D$150,MATCH(A5,Akaun!$A$5:$A$150,0)),"")}
B6: {=IFERROR(INDEX(Akaun!$C$5:$C$150,MATCH(A6,Akaun!$A$5:$A$150,0)),"")} | C6: {=IFERROR(INDEX(Akaun!$D$5:$D$150,MATCH(A6,Akaun!$A$5:$A$150,0)),"")}
B7: {=IFERROR(INDEX(Akaun!$C$5:$C$150,MATCH(A7,Akaun!$A$5:$A$150,0)),"")} | C7: {=IFERROR(INDEX(Akaun!$D$5:$D$150,MATCH(A7,Akaun!$A$5:$A$150,0)),"")}
B8: {=IFERROR(INDEX(Akaun!$C$5:$C$150,MATCH(A8,Akaun!$A$5:$A$150,0)),"")} | C8: {=IFERROR(INDEX(Akaun!$D$5:$D$150,MATCH(A8,Akaun!$A$5:$A$150,0)),"")}
B9: {=IFERROR(INDEX(Akaun!$C$5:$C$150,MATCH(A9,Akaun!$A$5:$A$150,0)),"")} | C9: {=IFERROR(INDEX(Akaun!$D$5:$D$150,MATCH(A9,Akaun!$A$5:$A$150,0)),"")}
B10: {=IFERROR(INDEX(Akaun!$C$5:$C$150,MATCH(A10,Akaun!$A$5:$A$150,0)),"")} | C10: {=IFERROR(INDEX(Akaun!$D$5:$D$150,MATCH(A10,Akaun!$A$5:$A$150,0)),"")}
B11: {=IFERROR(INDEX(Akaun!$C$5:$C$150,MATCH(A11,Akaun!$A$5:$A$150,0)),"")} | C11: {=IFERROR(INDEX(Akaun!$D$5:$D$150,MATCH(A11,Akaun!$A$5:$A$150,0)),"")}
B12: {=IFERROR(INDEX(Akaun!$C$5:$C$150,MATCH(A12,Akaun!$A$5:$A$150,0)),"")} | C12: {=IFERROR(INDEX(Akaun!$D$5:$D$150,MATCH(A12,Akaun!$A$5:$A$150,0)),"")}
B13: {=IFERROR(INDEX(Akaun!$C$5:$C$150,MATCH(A13,Akaun!$A$5:$A$150,0)),"")} | C13: {=IFERROR(INDEX(Akaun!$D$5:$D$150,MATCH(A13,Akaun!$A$5:$A$150,0)),"")}
B14: {=IFERROR(INDEX(Akaun!$C$5:$C$150,MATCH(A14,Akaun!$A$5:$A$150,0)),"")} | C14: {=IFERROR(INDEX(Akaun!$D$5:$D$150,MATCH(A14,Akaun!$A$5:$A$150,0)),"")}
B15: {=IFERROR(INDEX(Akaun!$C$5:$C$150,MATCH(A15,Akaun!$A$5:$A$150,0)),"")} | C15: {=IFERROR(INDEX(Akaun!$D$5:$D$150,MATCH(A15,Akaun!$A$5:$A$150,0)),"")}
B16: {=IFERROR(INDEX(Akaun!$C$5:$C$150,MATCH(A16,Akaun!$A$5:$A$150,0)),"")} | C16: {=IFERROR(INDEX(Akaun!$D$5:$D$150,MATCH(A16,Akaun!$A$5:$A$150,0)),"")}
... B54: {=IFERROR(INDEX(Akaun!$C$5:$C$150,MATCH(A54,Akaun!$A$5:$A$150,0)),"")} | C54: {=IFERROR(INDEX(Akaun!$D$5:$D$150,MATCH(A54,Akaun!$A$5:$A$150,0)),"")}
A57: Jumlah | D57: =SUM(D5:D54) | E57: =SUM(E5:E54)
A58: Semakan (mesti sepadan sebelum pos) | B58: =IF(ROUND(D57-E57,2)=0,"SEIMBANG - sedia untuk pos","TIDAK SEIMBANG - beza RM"&TEXT(D57-E57,"#,##0.00"))

Sheet Daftar_Aset_Tetap
A1: DAFTAR ASET TETAP (FIXED ASSET REGISTER)
A2: Sub-lejar terperinci di sebalik akaun kawalan "Aset Tetap" (1040) dalam Akaun. Jumlah Nilai Buku Bersih di sini SEPATUTNYA sepadan dengan baki 1040 tolak 1045 di Imbangan_Duga - jika tidak, ada aset didaftar di sini tanpa dipos ke lejar, atau sebaliknya.
A4: Nama Aset | B4: Kategori | C4: Tarikh Perolehan | D4: Kos Asal (RM) | E4: Nilai Baki (RM) | F4: Jangka Hayat (tahun) | G4: Kaedah | H4: Kadar Baki Berkurangan (%) | I4: Susut Nilai Terkumpul (RM) | J4: Nilai Buku Bersih (RM) | K4: Susut Nilai Tahun Ini (RM)
I5: =IF(OR(D5="",F5=""),"",IF(G5="Baki Berkurangan",MIN(D5*(1-(1-H5/100)^MAX(0,MIN(YEARFRAC(C5,TODAY(),1),F5))),D5-E5),MIN(((D5-E5)/F5)*MAX(0,MIN(YEARFRAC(C5,TODAY(),1),F5)),D5-E5))) | J5: =IF(D5="","",D5-I5) | K5: =IF(D5="","",I5-(IF(G5="Baki Berkurangan",MIN(D5*(1-(1-H5/100)^MAX(0,MIN(YEARFRAC(C5,TODAY(),1)-1,F5))),D5-E5),MIN(((D5-E5)/F5)*MAX(0,MIN(YEARFRAC(C5,TODAY(),1)-1,F5)),D5-E5))))
I6: =IF(OR(D6="",F6=""),"",IF(G6="Baki Berkurangan",MIN(D6*(1-(1-H6/100)^MAX(0,MIN(YEARFRAC(C6,TODAY(),1),F6))),D6-E6),MIN(((D6-E6)/F6)*MAX(0,MIN(YEARFRAC(C6,TODAY(),1),F6)),D6-E6))) | J6: =IF(D6="","",D6-I6) | K6: =IF(D6="","",I6-(IF(G6="Baki Berkurangan",MIN(D6*(1-(1-H6/100)^MAX(0,MIN(YEARFRAC(C6,TODAY(),1)-1,F6))),D6-E6),MIN(((D6-E6)/F6)*MAX(0,MIN(YEARFRAC(C6,TODAY(),1)-1,F6)),D6-E6))))
I7: =IF(OR(D7="",F7=""),"",IF(G7="Baki Berkurangan",MIN(D7*(1-(1-H7/100)^MAX(0,MIN(YEARFRAC(C7,TODAY()),F7))),D7-E7),MIN(((D7-E7)/F7)*MAX(0,MIN(YEARFRAC(C7,TODAY()),F7)),D7-E7))) | J7: =IF(D7="","",D7-I7) | K7: =IF(D7="","",I7-(IF(G7="Baki Berkurangan",MIN(D7*(1-(1-H7/100)^MAX(0,MIN(YEARFRAC(C7,TODAY())-1,F7))),D7-E7),MIN(((D7-E7)/F7)*MAX(0,MIN(YEARFRAC(C7,TODAY())-1,F7)),D7-E7))))
I8: =IF(OR(D8="",F8=""),"",IF(G8="Baki Berkurangan",MIN(D8*(1-(1-H8/100)^MAX(0,MIN(YEARFRAC(C8,TODAY()),F8))),D8-E8),MIN(((D8-E8)/F8)*MAX(0,MIN(YEARFRAC(C8,TODAY()),F8)),D8-E8))) | J8: =IF(D8="","",D8-I8) | K8: =IF(D8="","",I8-(IF(G8="Baki Berkurangan",MIN(D8*(1-(1-H8/100)^MAX(0,MIN(YEARFRAC(C8,TODAY())-1,F8))),D8-E8),MIN(((D8-E8)/F8)*MAX(0,MIN(YEARFRAC(C8,TODAY())-1,F8)),D8-E8))))
I9: =IF(OR(D9="",F9=""),"",IF(G9="Baki Berkurangan",MIN(D9*(1-(1-H9/100)^MAX(0,MIN(YEARFRAC(C9,TODAY()),F9))),D9-E9),MIN(((D9-E9)/F9)*MAX(0,MIN(YEARFRAC(C9,TODAY()),F9)),D9-E9))) | J9: =IF(D9="","",D9-I9) | K9: =IF(D9="","",I9-(IF(G9="Baki Berkurangan",MIN(D9*(1-(1-H9/100)^MAX(0,MIN(YEARFRAC(C9,TODAY())-1,F9))),D9-E9),MIN(((D9-E9)/F9)*MAX(0,MIN(YEARFRAC(C9,TODAY())-1,F9)),D9-E9))))
I10: =IF(OR(D10="",F10=""),"",IF(G10="Baki Berkurangan",MIN(D10*(1-(1-H10/100)^MAX(0,MIN(YEARFRAC(C10,TODAY()),F10))),D10-E10),MIN(((D10-E10)/F10)*MAX(0,MIN(YEARFRAC(C10,TODAY()),F10)),D10-E10))) | J10: =IF(D10="","",D10-I10) | K10: =IF(D10="","",I10-(IF(G10="Baki Berkurangan",MIN(D10*(1-(1-H10/100)^MAX(0,MIN(YEARFRAC(C10,TODAY())-1,F10))),D10-E10),MIN(((D10-E10)/F10)*MAX(0,MIN(YEARFRAC(C10,TODAY())-1,F10)),D10-E10))))
I11: =IF(OR(D11="",F11=""),"",IF(G11="Baki Berkurangan",MIN(D11*(1-(1-H11/100)^MAX(0,MIN(YEARFRAC(C11,TODAY()),F11))),D11-E11),MIN(((D11-E11)/F11)*MAX(0,MIN(YEARFRAC(C11,TODAY()),F11)),D11-E11))) | J11: =IF(D11="","",D11-I11) | K11: =IF(D11="","",I11-(IF(G11="Baki Berkurangan",MIN(D11*(1-(1-H11/100)^MAX(0,MIN(YEARFRAC(C11,TODAY())-1,F11))),D11-E11),MIN(((D11-E11)/F11)*MAX(0,MIN(YEARFRAC(C11,TODAY())-1,F11)),D11-E11))))
I12: =IF(OR(D12="",F12=""),"",IF(G12="Baki Berkurangan",MIN(D12*(1-(1-H12/100)^MAX(0,MIN(YEARFRAC(C12,TODAY()),F12))),D12-E12),MIN(((D12-E12)/F12)*MAX(0,MIN(YEARFRAC(C12,TODAY()),F12)),D12-E12))) | J12: =IF(D12="","",D12-I12) | K12: =IF(D12="","",I12-(IF(G12="Baki Berkurangan",MIN(D12*(1-(1-H12/100)^MAX(0,MIN(YEARFRAC(C12,TODAY())-1,F12))),D12-E12),MIN(((D12-E12)/F12)*MAX(0,MIN(YEARFRAC(C12,TODAY())-1,F12)),D12-E12))))
I13: =IF(OR(D13="",F13=""),"",IF(G13="Baki Berkurangan",MIN(D13*(1-(1-H13/100)^MAX(0,MIN(YEARFRAC(C13,TODAY()),F13))),D13-E13),MIN(((D13-E13)/F13)*MAX(0,MIN(YEARFRAC(C13,TODAY()),F13)),D13-E13))) | J13: =IF(D13="","",D13-I13) | K13: =IF(D13="","",I13-(IF(G13="Baki Berkurangan",MIN(D13*(1-(1-H13/100)^MAX(0,MIN(YEARFRAC(C13,TODAY())-1,F13))),D13-E13),MIN(((D13-E13)/F13)*MAX(0,MIN(YEARFRAC(C13,TODAY())-1,F13)),D13-E13))))
I14: =IF(OR(D14="",F14=""),"",IF(G14="Baki Berkurangan",MIN(D14*(1-(1-H14/100)^MAX(0,MIN(YEARFRAC(C14,TODAY()),F14))),D14-E14),MIN(((D14-E14)/F14)*MAX(0,MIN(YEARFRAC(C14,TODAY()),F14)),D14-E14))) | J14: =IF(D14="","",D14-I14) | K14: =IF(D14="","",I14-(IF(G14="Baki Berkurangan",MIN(D14*(1-(1-H14/100)^MAX(0,MIN(YEARFRAC(C14,TODAY())-1,F14))),D14-E14),MIN(((D14-E14)/F14)*MAX(0,MIN(YEARFRAC(C14,TODAY())-1,F14)),D14-E14))))
I15: =IF(OR(D15="",F15=""),"",IF(G15="Baki Berkurangan",MIN(D15*(1-(1-H15/100)^MAX(0,MIN(YEARFRAC(C15,TODAY()),F15))),D15-E15),MIN(((D15-E15)/F15)*MAX(0,MIN(YEARFRAC(C15,TODAY()),F15)),D15-E15))) | J15: =IF(D15="","",D15-I15) | K15: =IF(D15="","",I15-(IF(G15="Baki Berkurangan",MIN(D15*(1-(1-H15/100)^MAX(0,MIN(YEARFRAC(C15,TODAY())-1,F15))),D15-E15),MIN(((D15-E15)/F15)*MAX(0,MIN(YEARFRAC(C15,TODAY())-1,F15)),D15-E15))))
I16: =IF(OR(D16="",F16=""),"",IF(G16="Baki Berkurangan",MIN(D16*(1-(1-H16/100)^MAX(0,MIN(YEARFRAC(C16,TODAY()),F16))),D16-E16),MIN(((D16-E16)/F16)*MAX(0,MIN(YEARFRAC(C16,TODAY()),F16)),D16-E16))) | J16: =IF(D16="","",D16-I16) | K16: =IF(D16="","",I16-(IF(G16="Baki Berkurangan",MIN(D16*(1-(1-H16/100)^MAX(0,MIN(YEARFRAC(C16,TODAY())-1,F16))),D16-E16),MIN(((D16-E16)/F16)*MAX(0,MIN(YEARFRAC(C16,TODAY())-1,F16)),D16-E16))))
I17: =IF(OR(D17="",F17=""),"",IF(G17="Baki Berkurangan",MIN(D17*(1-(1-H17/100)^MAX(0,MIN(YEARFRAC(C17,TODAY()),F17))),D17-E17),MIN(((D17-E17)/F17)*MAX(0,MIN(YEARFRAC(C17,TODAY()),F17)),D17-E17))) | J17: =IF(D17="","",D17-I17) | K17: =IF(D17="","",I17-(IF(G17="Baki Berkurangan",MIN(D17*(1-(1-H17/100)^MAX(0,MIN(YEARFRAC(C17,TODAY())-1,F17))),D17-E17),MIN(((D17-E17)/F17)*MAX(0,MIN(YEARFRAC(C17,TODAY())-1,F17)),D17-E17))))
I18: =IF(OR(D18="",F18=""),"",IF(G18="Baki Berkurangan",MIN(D18*(1-(1-H18/100)^MAX(0,MIN(YEARFRAC(C18,TODAY()),F18))),D18-E18),MIN(((D18-E18)/F18)*MAX(0,MIN(YEARFRAC(C18,TODAY()),F18)),D18-E18))) | J18: =IF(D18="","",D18-I18) | K18: =IF(D18="","",I18-(IF(G18="Baki Berkurangan",MIN(D18*(1-(1-H18/100)^MAX(0,MIN(YEARFRAC(C18,TODAY())-1,F18))),D18-E18),MIN(((D18-E18)/F18)*MAX(0,MIN(YEARFRAC(C18,TODAY())-1,F18)),D18-E18))))
... I54: =IF(OR(D54="",F54=""),"",IF(G54="Baki Berkurangan",MIN(D54*(1-(1-H54/100)^MAX(0,MIN(YEARFRAC(C54,TODAY()),F54))),D54-E54),MIN(((D54-E54)/F54)*MAX(0,MIN(YEARFRAC(C54,TODAY()),F54)),D54-E54))) | J54: =IF(D54="","",D54-I54) | K54: =IF(D54="","",I54-(IF(G54="Baki Berkurangan",MIN(D54*(1-(1-H54/100)^MAX(0,MIN(YEARFRAC(C54,TODAY())-1,F54))),D54-E54),MIN(((D54-E54)/F54)*MAX(0,MIN(YEARFRAC(C54,TODAY())-1,F54)),D54-E54))))
A55: JUMLAH | D55: =SUM(D5:D54) | I55: =SUM(I5:I54) | J55: =SUM(J5:J54) | K55: =SUM(K5:K54)
A57: Semakan lawan Akaun (1040 - 1045):
A58: Nilai Buku Bersih ikut Daftar (di atas) | B58: =J55
A59: Nilai Buku Bersih ikut Lejar (Akaun 1040 - 1045) | B59: =SUMIF(Imbangan_Duga!$A$5:$A$150,1040,Imbangan_Duga!$H$5:$H$150)+SUMIF(Imbangan_Duga!$A$5:$A$150,1045,Imbangan_Duga!$H$5:$H$150)
A60: Semakan: | B60: =IF(ROUND(B58-B59,2)=0,"SEPADAN","TIDAK SEPADAN - beza RM"&TEXT(B58-B59,"#,##0.00")&" - ada aset didaftar tanpa dipos, atau sebaliknya")
A62: Nota ketepatan: "Susut Nilai Tahun Ini" (lajur K) disahkan tepat kepada sen untuk kedua-dua kaedah. "Susut Nilai Terkumpul" (lajur I, angka kumulatif sejak tarikh perolehan) mungkin berbeza beberapa ringgit sahaja daripada pengiraan manual disebabkan cara YEARFRAC kira bilangan hari - bukan ralat logik, hanya ketidaktepatan kecil pada angka kumulatif jangka panjang. Angka yang benar-benar dipos setiap tahun (lajur K) tidak terjejas.

Sheet Transaksi
A1: TRANSAKSI (TRANSACTION HEADERS)
A2: Satu baris = satu transaksi/resit/PV. Baris di bawah adalah CONTOH sahaja.
A3: SEMUA BARIS DI BAWAH INI IALAH CONTOH - PADAM SEBELUM GUNA SEBENAR
A4: ID Transaksi | B4: Tarikh | C4: Perkara | D4: No. PV / Rujukan | E4: Kaedah | F4: Status | G4: URL Resit / Baucar
A5: CONTOH-0000 | B5: 2026-01-01 | C5: Baki pembukaan tahun kewangan 2026 | D5: BA-2026 | E5: Bank | F5: Disahkan
A6: CONTOH-0001 | B6: 2026-01-15 | C6: Fi masuk ahli baharu | D6: PV-0001 | E6: Tunai | F6: Disahkan
A7: CONTOH-0002 | B7: 2026-01-20 | C7: Bayaran sewa pejabat Januari | D7: PV-0002 | E7: Bank | F7: Disahkan
A8: CONTOH-0003 | B8: 2026-01-25 | C8: Faedah/Hibah bank atas baki bulan Januari | D8: PV-0003 | E8: Bank | F8: Disahkan
A9: CONTOH-0004 | B9: 2026-01-28 | C9: Kontra: pindah tunai ke bank | D9: PV-0004 | E9: Bank | F9: Disahkan
A10: T-0000 | B10: 46280 | C10: Bank | D10: dfds | E10: Online | F10: Disahkan
A11: T-0001 | B11: 46280 | C11: Kontra / Pindahan | D11: 43 | E11: Kontra | F11: Disahkan

Sheet Baris_Transaksi
A1: BARIS TRANSAKSI (LEDGER LINES)
A2: Setiap transaksi ada 2+ baris. Jumlah Debit mesti sama dengan Jumlah Kredit bagi SETIAP ID Transaksi.
A4: ID Baris | B4: ID Transaksi | C4: Kod Akaun | D4: Debit | E4: Kredit | F4: Memo | G4: Kumpulan Aliran Tunai (auto)
A5: L-001 | B5: CONTOH-0000 | C5: 1010 | D5: 5000 | E5: 0 | F5: Baki awal tunai | G5: {=IF(C5="","",INDEX(Akaun!$F$5:$F$150,MATCH(C5,Akaun!$A$5:$A$150,0)))}
A6: L-002 | B6: CONTOH-0000 | C6: 1020 | D6: 50000 | E6: 0 | F6: Baki awal bank | G6: {=IF(C6="","",INDEX(Akaun!$F$5:$F$150,MATCH(C6,Akaun!$A$5:$A$150,0)))}
A7: L-003 | B7: CONTOH-0000 | C7: 1030 | D7: 20000 | E7: 0 | F7: Baki awal deposit tetap | G7: {=IF(C7="","",INDEX(Akaun!$F$5:$F$150,MATCH(C7,Akaun!$A$5:$A$150,0)))}
A8: L-004 | B8: CONTOH-0000 | C8: 3010 | D8: 0 | E8: 60000 | F8: Baki awal modal syer | G8: {=IF(C8="","",INDEX(Akaun!$F$5:$F$150,MATCH(C8,Akaun!$A$5:$A$150,0)))}
A9: L-005 | B9: CONTOH-0000 | C9: 3020 | D9: 0 | E9: 15000 | F9: Baki awal rizab statutori | G9: {=IF(C9="","",INDEX(Akaun!$F$5:$F$150,MATCH(C9,Akaun!$A$5:$A$150,0)))}
A10: L-006 | B10: CONTOH-0001 | C10: 1010 | D10: 1200 | E10: 0 | F10: Terima fi masuk ahli baharu | G10: {=IF(C10="","",INDEX(Akaun!$F$5:$F$150,MATCH(C10,Akaun!$A$5:$A$150,0)))}
A11: L-007 | B11: CONTOH-0001 | C11: 4010 | D11: 0 | E11: 1200 | F11: Fi masuk ahli baharu | G11: {=IF(C11="","",INDEX(Akaun!$F$5:$F$150,MATCH(C11,Akaun!$A$5:$A$150,0)))}
A12: L-008 | B12: CONTOH-0002 | C12: 5010 | D12: 800 | E12: 0 | F12: Sewa pejabat Januari | G12: {=IF(C12="","",INDEX(Akaun!$F$5:$F$150,MATCH(C12,Akaun!$A$5:$A$150,0)))}
A13: L-009 | B13: CONTOH-0002 | C13: 1020 | D13: 0 | E13: 800 | F13: Bayar melalui bank | G13: {=IF(C13="","",INDEX(Akaun!$F$5:$F$150,MATCH(C13,Akaun!$A$5:$A$150,0)))}
A14: L-010 | B14: CONTOH-0003 | C14: 1020 | D14: 300 | E14: 0 | F14: Terima faedah | G14: {=IF(C14="","",INDEX(Akaun!$F$5:$F$150,MATCH(C14,Akaun!$A$5:$A$150,0)))}
A15: L-011 | B15: CONTOH-0003 | C15: 4020 | D15: 0 | E15: 300 | F15: Faedah/Hibah bank atas baki deposit | G15: {=IF(C15="","",INDEX(Akaun!$F$5:$F$150,MATCH(C15,Akaun!$A$5:$A$150,0)))}
A16: L-012 | B16: CONTOH-0004 | C16: 1020 | D16: 2000 | E16: 0 | F16: Kontra dari tunai | G16: {=IF(C16="","",INDEX(Akaun!$F$5:$F$150,MATCH(C16,Akaun!$A$5:$A$150,0)))}
... A19: L-015 | B19: T-0000 | C19: 1020 | D19: 0 | E19: 300 | F19: dfds | G19: {=IF(C19="","",INDEX(Akaun!$F$5:$F$150,MATCH(C19,Akaun!$A$5:$A$150,0)))}
A20: L-016 | B20: T-0001 | C20: 1080 | D20: 34543 | E20: 0 | F20: 43 | G20: {=IF(C20="","",INDEX(Akaun!$F$5:$F$150,MATCH(C20,Akaun!$A$5:$A$150,0)))}
A21: L-017 | B21: T-0001 | C21: 1010 | D21: 0 | E21: 34543 | F21: 43 | G21: {=IF(C21="","",INDEX(Akaun!$F$5:$F$150,MATCH(C21,Akaun!$A$5:$A$150,0)))}
G22: {=IF(C22="","",INDEX(Akaun!$F$5:$F$150,MATCH(C22,Akaun!$A$5:$A$150,0)))}
G23: {=IF(C23="","",INDEX(Akaun!$F$5:$F$150,MATCH(C23,Akaun!$A$5:$A$150,0)))}
G24: {=IF(C24="","",INDEX(Akaun!$F$5:$F$150,MATCH(C24,Akaun!$A$5:$A$150,0)))}
G25: {=IF(C25="","",INDEX(Akaun!$F$5:$F$150,MATCH(C25,Akaun!$A$5:$A$150,0)))}
G26: {=IF(C26="","",INDEX(Akaun!$F$5:$F$150,MATCH(C26,Akaun!$A$5:$A$150,0)))}
G27: {=IF(C27="","",INDEX(Akaun!$F$5:$F$150,MATCH(C27,Akaun!$A$5:$A$150,0)))}
G28: {=IF(C28="","",INDEX(Akaun!$F$5:$F$150,MATCH(C28,Akaun!$A$5:$A$150,0)))}
G29: {=IF(C29="","",INDEX(Akaun!$F$5:$F$150,MATCH(C29,Akaun!$A$5:$A$150,0)))}
G30: {=IF(C30="","",INDEX(Akaun!$F$5:$F$150,MATCH(C30,Akaun!$A$5:$A$150,0)))}
G31: {=IF(C31="","",INDEX(Akaun!$F$5:$F$150,MATCH(C31,Akaun!$A$5:$A$150,0)))}
G32: {=IF(C32="","",INDEX(Akaun!$F$5:$F$150,MATCH(C32,Akaun!$A$5:$A$150,0)))}
G33: {=IF(C33="","",INDEX(Akaun!$F$5:$F$150,MATCH(C33,Akaun!$A$5:$A$150,0)))}
... G500: {=IF(C500="","",INDEX(Akaun!$F$5:$F$150,MATCH(C500,Akaun!$A$5:$A$150,0)))}

Sheet Log_Perubahan
A1: Tarikh & Masa | B1: Pengguna | C1: Helaian | D1: Sel | E1: Nilai Lama | F1: Nilai Baharu | G1: Sebab
A2: 46280.003 | B2: reysourcez.ent@gmail.com | C2: Baris_Transaksi | D2: E5 | E2: 0 | F2: 13123 | G2: salah taip jumlah

Sheet Imbangan_Duga
A1: IMBANGAN DUGA (TRIAL BALANCE)
A2: Formula pra-isi sampai baris 150 supaya akaun baharu (Tambah Akaun) automatik terpakai tanpa ubah julat.
A4: Kod Akaun | B4: Nama Akaun | C4: Jenis | D4: Jumlah Debit | E4: Jumlah Kredit | F4: Baki Debit | G4: Baki Kredit | H4: Baki Bersih (bertanda)
A5: =Akaun!A5 | B5: =Akaun!C5 | C5: =Akaun!D5 | D5: =SUMIF(Baris_Transaksi!$C$5:$C$500,A5,Baris_Transaksi!$D$5:$D$500) | E5: =SUMIF(Baris_Transaksi!$C$5:$C$500,A5,Baris_Transaksi!$E$5:$E$500) | F5: =IF(D5-E5>0,D5-E5,0) | G5: =IF(E5-D5>0,E5-D5,0) | H5: =IF(OR(C5="Aset",C5="Perbelanjaan"),D5-E5,E5-D5)
A6: =Akaun!A6 | B6: =Akaun!C6 | C6: =Akaun!D6 | D6: =SUMIF(Baris_Transaksi!$C$5:$C$500,A6,Baris_Transaksi!$D$5:$D$500) | E6: =SUMIF(Baris_Transaksi!$C$5:$C$500,A6,Baris_Transaksi!$E$5:$E$500) | F6: =IF(D6-E6>0,D6-E6,0) | G6: =IF(E6-D6>0,E6-D6,0) | H6: =IF(OR(C6="Aset",C6="Perbelanjaan"),D6-E6,E6-D6)
A7: =Akaun!A7 | B7: =Akaun!C7 | C7: =Akaun!D7 | D7: =SUMIF(Baris_Transaksi!$C$5:$C$500,A7,Baris_Transaksi!$D$5:$D$500) | E7: =SUMIF(Baris_Transaksi!$C$5:$C$500,A7,Baris_Transaksi!$E$5:$E$500) | F7: =IF(D7-E7>0,D7-E7,0) | G7: =IF(E7-D7>0,E7-D7,0) | H7: =IF(OR(C7="Aset",C7="Perbelanjaan"),D7-E7,E7-D7)
A8: =Akaun!A8 | B8: =Akaun!C8 | C8: =Akaun!D8 | D8: =SUMIF(Baris_Transaksi!$C$5:$C$500,A8,Baris_Transaksi!$D$5:$D$500) | E8: =SUMIF(Baris_Transaksi!$C$5:$C$500,A8,Baris_Transaksi!$E$5:$E$500) | F8: =IF(D8-E8>0,D8-E8,0) | G8: =IF(E8-D8>0,E8-D8,0) | H8: =IF(OR(C8="Aset",C8="Perbelanjaan"),D8-E8,E8-D8)
A9: =Akaun!A9 | B9: =Akaun!C9 | C9: =Akaun!D9 | D9: =SUMIF(Baris_Transaksi!$C$5:$C$500,A9,Baris_Transaksi!$D$5:$D$500) | E9: =SUMIF(Baris_Transaksi!$C$5:$C$500,A9,Baris_Transaksi!$E$5:$E$500) | F9: =IF(D9-E9>0,D9-E9,0) | G9: =IF(E9-D9>0,E9-D9,0) | H9: =IF(OR(C9="Aset",C9="Perbelanjaan"),D9-E9,E9-D9)
A10: =Akaun!A10 | B10: =Akaun!C10 | C10: =Akaun!D10 | D10: =SUMIF(Baris_Transaksi!$C$5:$C$500,A10,Baris_Transaksi!$D$5:$D$500) | E10: =SUMIF(Baris_Transaksi!$C$5:$C$500,A10,Baris_Transaksi!$E$5:$E$500) | F10: =IF(D10-E10>0,D10-E10,0) | G10: =IF(E10-D10>0,E10-D10,0) | H10: =IF(OR(C10="Aset",C10="Perbelanjaan"),D10-E10,E10-D10)
A11: =Akaun!A11 | B11: =Akaun!C11 | C11: =Akaun!D11 | D11: =SUMIF(Baris_Transaksi!$C$5:$C$500,A11,Baris_Transaksi!$D$5:$D$500) | E11: =SUMIF(Baris_Transaksi!$C$5:$C$500,A11,Baris_Transaksi!$E$5:$E$500) | F11: =IF(D11-E11>0,D11-E11,0) | G11: =IF(E11-D11>0,E11-D11,0) | H11: =IF(OR(C11="Aset",C11="Perbelanjaan"),D11-E11,E11-D11)
A12: =Akaun!A12 | B12: =Akaun!C12 | C12: =Akaun!D12 | D12: =SUMIF(Baris_Transaksi!$C$5:$C$500,A12,Baris_Transaksi!$D$5:$D$500) | E12: =SUMIF(Baris_Transaksi!$C$5:$C$500,A12,Baris_Transaksi!$E$5:$E$500) | F12: =IF(D12-E12>0,D12-E12,0) | G12: =IF(E12-D12>0,E12-D12,0) | H12: =IF(OR(C12="Aset",C12="Perbelanjaan"),D12-E12,E12-D12)
A13: =Akaun!A13 | B13: =Akaun!C13 | C13: =Akaun!D13 | D13: =SUMIF(Baris_Transaksi!$C$5:$C$500,A13,Baris_Transaksi!$D$5:$D$500) | E13: =SUMIF(Baris_Transaksi!$C$5:$C$500,A13,Baris_Transaksi!$E$5:$E$500) | F13: =IF(D13-E13>0,D13-E13,0) | G13: =IF(E13-D13>0,E13-D13,0) | H13: =IF(OR(C13="Aset",C13="Perbelanjaan"),D13-E13,E13-D13)
A14: =Akaun!A14 | B14: =Akaun!C14 | C14: =Akaun!D14 | D14: =SUMIF(Baris_Transaksi!$C$5:$C$500,A14,Baris_Transaksi!$D$5:$D$500) | E14: =SUMIF(Baris_Transaksi!$C$5:$C$500,A14,Baris_Transaksi!$E$5:$E$500) | F14: =IF(D14-E14>0,D14-E14,0) | G14: =IF(E14-D14>0,E14-D14,0) | H14: =IF(OR(C14="Aset",C14="Perbelanjaan"),D14-E14,E14-D14)
A15: =Akaun!A15 | B15: =Akaun!C15 | C15: =Akaun!D15 | D15: =SUMIF(Baris_Transaksi!$C$5:$C$500,A15,Baris_Transaksi!$D$5:$D$500) | E15: =SUMIF(Baris_Transaksi!$C$5:$C$500,A15,Baris_Transaksi!$E$5:$E$500) | F15: =IF(D15-E15>0,D15-E15,0) | G15: =IF(E15-D15>0,E15-D15,0) | H15: =IF(OR(C15="Aset",C15="Perbelanjaan"),D15-E15,E15-D15)
A16: =Akaun!A16 | B16: =Akaun!C16 | C16: =Akaun!D16 | D16: =SUMIF(Baris_Transaksi!$C$5:$C$500,A16,Baris_Transaksi!$D$5:$D$500) | E16: =SUMIF(Baris_Transaksi!$C$5:$C$500,A16,Baris_Transaksi!$E$5:$E$500) | F16: =IF(D16-E16>0,D16-E16,0) | G16: =IF(E16-D16>0,E16-D16,0) | H16: =IF(OR(C16="Aset",C16="Perbelanjaan"),D16-E16,E16-D16)
... A150: =Akaun!A150 | B150: =Akaun!C150 | C150: =Akaun!D150 | D150: =SUMIF(Baris_Transaksi!$C$5:$C$500,A150,Baris_Transaksi!$D$5:$D$500) | E150: =SUMIF(Baris_Transaksi!$C$5:$C$500,A150,Baris_Transaksi!$E$5:$E$500) | F150: =IF(D150-E150>0,D150-E150,0) | G150: =IF(E150-D150>0,E150-D150,0) | H150: =IF(OR(C150="Aset",C150="Perbelanjaan"),D150-E150,E150-D150)
A151: JUMLAH | F151: =SUM(F5:F150) | G151: =SUM(G5:G150)
A153: Semakan: | B153: =IF(ROUND(F151-G151,2)=0,"SEIMBANG","TIDAK SEIMBANG - beza RM"&TEXT(F151-G151,"#,##0.00"))

Sheet UR
A1: AKAUN UNTUNG RUGI (INCOME STATEMENT)
A2: Bagi tempoh 1 Januari 2026 hingga 31 Januari 2026 (data contoh). Cukai, Zakat, Honorarium dan KWA kini di APK, bukan di sini.
A4: HASIL
A5: Fi Masuk | B5: =SUMIF(Imbangan_Duga!$A$5:$A$150,4010,Imbangan_Duga!$H$5:$H$150)
A6: Faedah Bank | B6: =SUMIF(Imbangan_Duga!$A$5:$A$150,4020,Imbangan_Duga!$H$5:$H$150)
A7: Hibah Bank | B7: =SUMIF(Imbangan_Duga!$A$5:$A$150,4030,Imbangan_Duga!$H$5:$H$150)
A8: Jualan Runcit | B8: =SUMIF(Imbangan_Duga!$A$5:$A$150,4040,Imbangan_Duga!$H$5:$H$150)
A9: Pendapatan Perkhidmatan | B9: =SUMIF(Imbangan_Duga!$A$5:$A$150,4050,Imbangan_Duga!$H$5:$H$150)
A10: Pendapatan Latihan & Kursus | B10: =SUMIF(Imbangan_Duga!$A$5:$A$150,4060,Imbangan_Duga!$H$5:$H$150)
A11: Jualan Makanan & Minuman | B11: =SUMIF(Imbangan_Duga!$A$5:$A$150,4070,Imbangan_Duga!$H$5:$H$150)
A12: Jualan Ayam & Produk Sembelihan | B12: =SUMIF(Imbangan_Duga!$A$5:$A$150,4080,Imbangan_Duga!$H$5:$H$150)
A13: JUMLAH HASIL | B13: =SUMIF(Imbangan_Duga!$C$5:$C$150,"Hasil",Imbangan_Duga!$H$5:$H$150)
A15: PERBELANJAAN OPERASI
A16: Perbelanjaan Pejabat | B16: =SUMIF(Imbangan_Duga!$A$5:$A$150,5010,Imbangan_Duga!$H$5:$H$150)
A17: Perbelanjaan Lembaga | B17: =SUMIF(Imbangan_Duga!$A$5:$A$150,5020,Imbangan_Duga!$H$5:$H$150)
A18: Gaji dan Elaun | B18: =SUMIF(Imbangan_Duga!$A$5:$A$150,5030,Imbangan_Duga!$H$5:$H$150)
A19: Alatulis dan Percetakan | B19: =SUMIF(Imbangan_Duga!$A$5:$A$150,5040,Imbangan_Duga!$H$5:$H$150)
A20: Fi Juruaudit | B20: =SUMIF(Imbangan_Duga!$A$5:$A$150,5050,Imbangan_Duga!$H$5:$H$150)
A21: Fi Perakaunan | B21: =SUMIF(Imbangan_Duga!$A$5:$A$150,5060,Imbangan_Duga!$H$5:$H$150)
A22: Caj Bank | B22: =SUMIF(Imbangan_Duga!$A$5:$A$150,5070,Imbangan_Duga!$H$5:$H$150)
A23: Mesyuarat Agung Tahunan | B23: =SUMIF(Imbangan_Duga!$A$5:$A$150,5080,Imbangan_Duga!$H$5:$H$150)
A24: Mesyuarat Agung Khas | B24: =SUMIF(Imbangan_Duga!$A$5:$A$150,5090,Imbangan_Duga!$H$5:$H$150)
A25: Internet dan Telefon | B25: =SUMIF(Imbangan_Duga!$A$5:$A$150,5150,Imbangan_Duga!$H$5:$H$150)
A26: Susut Nilai Aset | B26: =SUMIF(Imbangan_Duga!$A$5:$A$150,5160,Imbangan_Duga!$H$5:$H$150)
A27: Belian Runcit | B27: =SUMIF(Imbangan_Duga!$A$5:$A$150,5180,Imbangan_Duga!$H$5:$H$150)
A28: Kos Latihan & Kursus | B28: =SUMIF(Imbangan_Duga!$A$5:$A$150,5190,Imbangan_Duga!$H$5:$H$150)
A29: Kos Bahan Mentah F&B | B29: =SUMIF(Imbangan_Duga!$A$5:$A$150,5200,Imbangan_Duga!$H$5:$H$150)
A30: Belian Ayam Hidup | B30: =SUMIF(Imbangan_Duga!$A$5:$A$150,5210,Imbangan_Duga!$H$5:$H$150)
A31: Kos Sembelihan & Pemprosesan | B31: =SUMIF(Imbangan_Duga!$A$5:$A$150,5220,Imbangan_Duga!$H$5:$H$150)
A32: Fi Pensijilan Halal | B32: =SUMIF(Imbangan_Duga!$A$5:$A$150,5230,Imbangan_Duga!$H$5:$H$150)
A33: Pelbagai Perbelanjaan | B33: =SUMIF(Imbangan_Duga!$A$5:$A$150,5170,Imbangan_Duga!$H$5:$H$150)
A34: JUMLAH PERBELANJAAN OPERASI | B34: =SUMIF(Imbangan_Duga!$C$5:$C$150,"Perbelanjaan",Imbangan_Duga!$H$5:$H$150)
A36: LEBIHAN BERSIH (SURPLUS) - SEBELUM PEMBAHAGIAN | B36: =B13-B34

Sheet APK
A1: AKAUN PEMBAHAGIAN KEUNTUNGAN (APK)
A2: Bagi tempoh 1 Januari 2026 hingga 31 Januari 2026 (data contoh). Lajur kuning = keputusan Lembaga, isi semasa mesyuarat.
A4: Lebihan Bersih Tahun Semasa (daripada UR) | B4: =UR!B36
A6: TOLAK: PEMBAHAGIAN BERKANUN
A7: Kumpulan Wang Rizab Statutori (Tetapan!C15) | B7: =B4*Tetapan!C15/100
A8: Kumpulan Wang Amanah Pendidikan Koperasi (Tetapan!C16) | B8: =B4*Tetapan!C16/100
A9: Kumpulan Wang Amanah Pembangunan Koperasi (Tetapan!C17) | B9: =B4*Tetapan!C17/100
A10: JUMLAH PEMBAHAGIAN BERKANUN | B10: =SUM(B7:B9)
A12: LEBIHAN SELEPAS PEMBAHAGIAN BERKANUN | B12: =B4-B10
A14: TOLAK: PERUNTUKAN
A15: Peruntukan Cukai Pendapatan (isi anggaran Lembaga) | B15: 0
A16: Peruntukan Zakat (isi anggaran Lembaga) | B16: 0
A17: JUMLAH PERUNTUKAN | B17: =SUM(B15:B16)
A19: TOLAK: LAIN-LAIN PEMBAHAGIAN (cadangan Lembaga)
A20: Dividen Atas Modal Syer (isi cadangan) | B20: 0
A21: Dividen Atas Modal Yuran (isi cadangan) | B21: 0
A22: Honorarium Lembaga (isi cadangan) | B22: 0
A23: JUMLAH LAIN-LAIN PEMBAHAGIAN | B23: =SUM(B20:B22)
A25: BAKI KEUNTUNGAN BELUM DIBAHAGI-BAHAGIKAN | B25: =B12-B17-B23
A27: Tambah: Lebihan Terkumpul Pada Awal Tahun | B27: =SUMIF(Imbangan_Duga!$A$5:$A$150,3030,Imbangan_Duga!$H$5:$H$150)
A28: LEBIHAN TERKUMPUL PADA AKHIR TAHUN (unjuran) | B28: =B25+B27
A30: Nota
A31: Baris B28 ialah UNJURAN untuk keputusan Lembaga, bukan baki sebenar KKK - KKK kekal tunjuk baki sebenar lejar. Selepas Lembaga luluskan angka di atas, pos SATU transaksi seimbang: Debit Lebihan Terkumpul (3030) sebanyak jumlah yang diluluskan, Kredit setiap akaun liabiliti berkaitan (Rizab Statutori 3020, KWA Pendidikan Belum Dibayar 2100, KWA Pembangunan Belum Dibayar 2110, Cukai Belum Dibayar 2070, Zakat Belum Dibayar 2080, Dividen Diisytiharkan 2020, Honorarium Belum Dibayar 2090). Selepas itu KKK automatik betul.

Sheet KKK
A1: KUNCI KIRA-KIRA (BALANCE SHEET)
A2: Setakat 31 Januari 2026 (data contoh)
A4: ASET
A5: Wang Di Tangan | B5: =SUMIF(Imbangan_Duga!$A$5:$A$150,1010,Imbangan_Duga!$H$5:$H$150)
A6: Bank | B6: =SUMIF(Imbangan_Duga!$A$5:$A$150,1020,Imbangan_Duga!$H$5:$H$150)
A7: Deposit Tetap | B7: =SUMIF(Imbangan_Duga!$A$5:$A$150,1030,Imbangan_Duga!$H$5:$H$150)
A8: Aset Tetap | B8: =SUMIF(Imbangan_Duga!$A$5:$A$150,1040,Imbangan_Duga!$H$5:$H$150)
A9: Akaun Deposit Koperasi | B9: =SUMIF(Imbangan_Duga!$A$5:$A$150,1050,Imbangan_Duga!$H$5:$H$150)
A10: Inventori Runcit | B10: =SUMIF(Imbangan_Duga!$A$5:$A$150,1060,Imbangan_Duga!$H$5:$H$150)
A11: Inventori Ayam & Produk Sembelihan | B11: =SUMIF(Imbangan_Duga!$A$5:$A$150,1070,Imbangan_Duga!$H$5:$H$150)
A12: JUMLAH ASET | B12: =SUMIF(Imbangan_Duga!$C$5:$C$150,"Aset",Imbangan_Duga!$H$5:$H$150)
A14: LIABILITI
A15: Pelbagai Pemiutang | B15: =SUMIF(Imbangan_Duga!$A$5:$A$150,2010,Imbangan_Duga!$H$5:$H$150)
A16: Dividen Diisytiharkan | B16: =SUMIF(Imbangan_Duga!$A$5:$A$150,2020,Imbangan_Duga!$H$5:$H$150)
A17: JUMLAH LIABILITI | B17: =SUMIF(Imbangan_Duga!$C$5:$C$150,"Liabiliti",Imbangan_Duga!$H$5:$H$150)
A19: EKUITI AHLI
A20: Modal Syer Ahli | B20: =SUMIF(Imbangan_Duga!$A$5:$A$150,3010,Imbangan_Duga!$H$5:$H$150)
A21: Rizab Statutori | B21: =SUMIF(Imbangan_Duga!$A$5:$A$150,3020,Imbangan_Duga!$H$5:$H$150)
A22: Lebihan Terkumpul (Tahun Lepas) | B22: =SUMIF(Imbangan_Duga!$A$5:$A$150,3030,Imbangan_Duga!$H$5:$H$150)
A23: Lebihan Tahun Semasa | B23: =UR!B36
A24: JUMLAH EKUITI AHLI | B24: =SUM(B20:B23)
A26: JUMLAH LIABILITI + EKUITI | B26: =B17+B24
A28: Semakan: | B28: =IF(ROUND(B12-B26,2)=0,"SEIMBANG","TIDAK SEIMBANG - beza RM"&TEXT(B12-B26,"#,##0.00"))

Sheet AT
A1: PENYATA ALIRAN TUNAI (CASH FLOW STATEMENT)
A2: Bagi tempoh 1 Januari 2026 hingga 31 Januari 2026 (data contoh) — kaedah tidak langsung (indirect method)
A4: AKTIVITI OPERASI
A5: Lebihan bersih (daripada UR) | B5: =UR!B36
A6: Pelarasan bukan tunai (susut nilai, dll.) | B6: 0
A7: Perubahan modal kerja (perlu data 2+ tempoh) | B7: 0
A8: TUNAI BERSIH DARIPADA OPERASI | B8: =SUM(B5:B7)
A10: AKTIVITI PELABURAN
A11: Pergerakan bersih akaun pelaburan/aset tetap (cth. Deposit Tetap, Tanah, Bangunan) | B11: =SUMIFS(Baris_Transaksi!$E$5:$E$500,Baris_Transaksi!$G$5:$G$500,"Pelaburan",Baris_Transaksi!$B$5:$B$500,"<>"&Tetapan!$C$18)-SUMIFS(Baris_Transaksi!$D$5:$D$500,Baris_Transaksi!$G$5:$G$500,"Pelaburan",Baris_Transaksi!$B$5:$B$500,"<>"&Tetapan!$C$18)
A12: TUNAI BERSIH DARIPADA PELABURAN | B12: =B11
A14: AKTIVITI PEMBIAYAAN
A15: Pergerakan bersih modal syer, simpanan ahli, pinjaman & dividen dibayar | B15: =SUMIFS(Baris_Transaksi!$E$5:$E$500,Baris_Transaksi!$G$5:$G$500,"Pembiayaan",Baris_Transaksi!$B$5:$B$500,"<>"&Tetapan!$C$18)-SUMIFS(Baris_Transaksi!$D$5:$D$500,Baris_Transaksi!$G$5:$G$500,"Pembiayaan",Baris_Transaksi!$B$5:$B$500,"<>"&Tetapan!$C$18)
A16: TUNAI BERSIH DARIPADA PEMBIAYAAN | B16: =B15
A17: AKTIVITI BERKANUN (Bayaran Berkanun & Agihan)
A18: Bayaran kepada KWRS/KWA Pendidikan/Pembangunan/Cukai/Zakat/Honorarium/Dividen (hanya bahagian dibayar) | B18: =-SUMIFS(Baris_Transaksi!$D$5:$D$500,Baris_Transaksi!$G$5:$G$500,"Berkanun",Baris_Transaksi!$B$5:$B$500,"<>"&Tetapan!$C$18)
A19: TUNAI BERSIH DARIPADA AKTIVITI BERKANUN | B19: =B18
A21: PERUBAHAN BERSIH TUNAI (B8+B12+B16+B19) | B21: =B8+B12+B16+B19
A23: Tunai & bank pada awal tempoh (Wang Di Tangan + Bank + Wang Runcit) | B23: =SUMIFS(Baris_Transaksi!$D$5:$D$500,Baris_Transaksi!$C$5:$C$500,1010,Baris_Transaksi!$B$5:$B$500,Tetapan!$C$18)-SUMIFS(Baris_Transaksi!$E$5:$E$500,Baris_Transaksi!$C$5:$C$500,1010,Baris_Transaksi!$B$5:$B$500,Tetapan!$C$18)+SUMIFS(Baris_Transaksi!$D$5:$D$500,Baris_Transaksi!$C$5:$C$500,1020,Baris_Transaksi!$B$5:$B$500,Tetapan!$C$18)-SUMIFS(Baris_Transaksi!$E$5:$E$500,Baris_Transaksi!$C$5:$C$500,1020,Baris_Transaksi!$B$5:$B$500,Tetapan!$C$18)+SUMIFS(Baris_Transaksi!$D$5:$D$500,Baris_Transaksi!$C$5:$C$500,1080,Baris_Transaksi!$B$5:$B$500,Tetapan!$C$18)-SUMIFS(Baris_Transaksi!$E$5:$E$500,Baris_Transaksi!$C$5:$C$500,1080,Baris_Transaksi!$B$5:$B$500,Tetapan!$C$18)
A24: TUNAI & BANK PADA AKHIR TEMPOH (dikira) | B24: =B23+B21
A25: Tunai & bank pada akhir tempoh (semakan bebas, dari Imbangan_Duga) | B25: =SUMIF(Imbangan_Duga!$A$5:$A$150,1010,Imbangan_Duga!$H$5:$H$150)+SUMIF(Imbangan_Duga!$A$5:$A$150,1020,Imbangan_Duga!$H$5:$H$150)+SUMIF(Imbangan_Duga!$A$5:$A$150,1080,Imbangan_Duga!$H$5:$H$150)
A27: Semakan: | B27: =IF(ROUND(B24-B25,2)=0,"SEIMBANG","TIDAK SEIMBANG - beza RM"&TEXT(B24-B25,"#,##0.00"))

Sheet Wang_Runcit
A1: WANG RUNCIT (PETTY CASH) — SEMAKAN
A2: Setiap perbelanjaan runcit dicatat terus: Debit akaun perbelanjaan, Kredit Wang Runcit (1080). Isi semula (float top-up): Debit Wang Runcit, Kredit Bank.
A4: Float ditetapkan / diisytiharkan (RM) - rujukan sahaja | B4: 500
A5: Baki mengikut buku (Wang Runcit, kod 1080) | B5: =SUMIF(Imbangan_Duga!$A$5:$A$150,1080,Imbangan_Duga!$H$5:$H$150)
A6: Tarikh pengiraan fizikal terakhir
A7: Baki dikira semasa pengiraan fizikal (kira duit sebenar dalam tin/peti)
A9: PERBEZAAN (Baki Buku - Baki Fizikal) | B9: =IF(B7="","",B5-B7)
A10: Status | B10: =IF(B7="","BELUM DIKIRA",IF(ROUND(B9,2)=0,"SEPADAN","PERLU SIASAT - lihat lajur Nota di Baris_Transaksi untuk perbelanjaan terbaru"))
A12: Nota
A13: Baki Buku di atas ialah baki SEBENAR akaun 1080 dalam lejar - bukan dikira daripada float. Sebelum guna helaian ini, catat SATU transaksi "wujudkan float": Debit Wang Runcit RM{float}, Kredit Bank/Wang Di Tangan RM{float}, dalam Baris_Transaksi. Selepas itu, setiap perbelanjaan runcit ialah Debit akaun perbelanjaan, Kredit Wang Runcit - baki di atas turun sendiri ikut perbelanjaan sebenar, tiada pengiraan tambahan diperlukan.

Sheet Cetak
A1: =Tetapan!C5
A2: PENYATA KEWANGAN
A3: Disediakan untuk Mesyuarat Lembaga
A5: RINGKASAN KEDUDUKAN KEWANGAN (AI)
A6: (Jalankan menu APZacct > Jana Ringkasan AI untuk isi bahagian ini. Kosong sehingga itu — tidak akan menghalang cetakan penyata di bawah.)
A13: =KKK!A1
A14: =KKK!A2
A15: =KKK!A4
A16: =KKK!A5 | B16: =KKK!B5
A17: =KKK!A6 | B17: =KKK!B6
A18: =KKK!A7 | B18: =KKK!B7
A19: =KKK!A8 | B19: =KKK!B8
A20: =KKK!A9 | B20: =KKK!B9
A21: =KKK!A10 | B21: =KKK!B10
A22: =KKK!A11 | B22: =KKK!B11
A23: =KKK!A12 | B23: =KKK!B12
A24: =KKK!A14
A25: =KKK!A15 | B25: =KKK!B15
A26: =KKK!A16 | B26: =KKK!B16
A27: =KKK!A17 | B27: =KKK!B17
A28: =KKK!A19
A29: =KKK!A20 | B29: =KKK!B20
A30: =KKK!A21 | B30: =KKK!B21
A31: =KKK!A22 | B31: =KKK!B22
A32: =KKK!A23 | B32: =KKK!B23
A33: =KKK!A24 | B33: =KKK!B24
A34: =KKK!A26 | B34: =KKK!B26
A35: =KKK!A28 | B35: =KKK!B28
A39: =UR!A1
A40: =UR!A2
A41: =UR!A4
A42: =UR!A5 | B42: =UR!B5
A43: =UR!A6 | B43: =UR!B6
A44: =UR!A7 | B44: =UR!B7
A45: =UR!A8 | B45: =UR!B8
A46: =UR!A9 | B46: =UR!B9
A47: =UR!A10 | B47: =UR!B10
A48: =UR!A11 | B48: =UR!B11
A49: =UR!A12 | B49: =UR!B12
A50: =UR!A13 | B50: =UR!B13
...
