Workbook

Sheet Nota
A1: NOTA-NOTA KEPADA AKAUN (NOTES TO THE ACCOUNTS) — TEMPLAT UMUM GP23
A2: Templat ini untuk MANA-MANA jenis koperasi, tanpa kira aktiviti. Formula TIDAK dikodkeras kepada kod akaun tertentu — setiap Nota bertanya "Berkaitan?" dan "Kod Akaun", diisi dengan kod SEBENAR koperasi anda sendiri (daripada helaian Akaun anda sendiri). Jika Tidak Berkaitan, biar kod kosong — baki tunjuk 0, itu betul.
A3: Nilai yang terpapar semasa ujian formula ini adalah DATA UJIAN/CONTOH sahaja — BUKAN kedudukan kewangan sebenar mana-mana koperasi. Jangan ambil sebarang angka di sini sebagai fakta perniagaan.
A5: NOTA 1 — MAKLUMAT UMUM (GP23 perenggan 16, Nota 1)
A6: Aktiviti utama | B6: [ISI] ◄ ISI
A7: Alamat berdaftar | B7: [ISI] ◄ ISI
A8: No. Pendaftaran SKM | B8: =IF(Tetapan!C6="","[ISI di Tetapan!C6]",Tetapan!C6) -> [ISI di Tetapan!C6]
A10: NOTA 2 — ASAS PENYEDIAAN PENYATA KEWANGAN (GP23 perenggan 16, Nota 2)
A11: Penyata kewangan ini disediakan mengikut piawaian perakaunan yang diluluskan di Malaysia (MPERS), sebagaimana diubahsuaikan oleh GP23: Garis Panduan Pelaporan Penyata Kewangan Koperasi, selaras dengan Akta Koperasi 1993 dan Peraturan-Peraturan Koperasi 2010. [ISI jika koperasi anda menggunakan piawaian lain]
A13: NOTA 3 — TARIKH PENGESAHAN PENYATA KEWANGAN (GP23 perenggan 16, Nota 3)
A14: Disahkan oleh Lembaga pada | B14: [ISI] ◄ ISI
A16: NOTA 4 — RINGKASAN POLISI PERAKAUNAN PENTING (GP23 perenggan 16, Nota 5)
A17: (a) Susut nilai — kaedah/kadar setiap aset (daripada Daftar_Aset_Tetap; kosong jika belum ada aset didaftar):
A18: Nama Aset | B18: Kategori | C18: Kaedah | D18: Kadar
A19: =IF(Daftar_Aset_Tetap!A5="","",Daftar_Aset_Tetap!A5) | B19: =IF(Daftar_Aset_Tetap!A5="","",Daftar_Aset_Tetap!B5) | C19: =IF(Daftar_Aset_Tetap!A5="","",Daftar_Aset_Tetap!G5) | D19: =IF(Daftar_Aset_Tetap!A5="","",Daftar_Aset_Tetap!H5)
A20: =IF(Daftar_Aset_Tetap!A6="","",Daftar_Aset_Tetap!A6) | B20: =IF(Daftar_Aset_Tetap!A6="","",Daftar_Aset_Tetap!B6) | C20: =IF(Daftar_Aset_Tetap!A6="","",Daftar_Aset_Tetap!G6) | D20: =IF(Daftar_Aset_Tetap!A6="","",Daftar_Aset_Tetap!H6)
A21: =IF(Daftar_Aset_Tetap!A7="","",Daftar_Aset_Tetap!A7) | B21: =IF(Daftar_Aset_Tetap!A7="","",Daftar_Aset_Tetap!B7) | C21: =IF(Daftar_Aset_Tetap!A7="","",Daftar_Aset_Tetap!G7) | D21: =IF(Daftar_Aset_Tetap!A7="","",Daftar_Aset_Tetap!H7)
A22: =IF(Daftar_Aset_Tetap!A8="","",Daftar_Aset_Tetap!A8) | B22: =IF(Daftar_Aset_Tetap!A8="","",Daftar_Aset_Tetap!B8) | C22: =IF(Daftar_Aset_Tetap!A8="","",Daftar_Aset_Tetap!G8) | D22: =IF(Daftar_Aset_Tetap!A8="","",Daftar_Aset_Tetap!H8)
A23: =IF(Daftar_Aset_Tetap!A9="","",Daftar_Aset_Tetap!A9) | B23: =IF(Daftar_Aset_Tetap!A9="","",Daftar_Aset_Tetap!B9) | C23: =IF(Daftar_Aset_Tetap!A9="","",Daftar_Aset_Tetap!G9) | D23: =IF(Daftar_Aset_Tetap!A9="","",Daftar_Aset_Tetap!H9)
A24: =IF(Daftar_Aset_Tetap!A10="","",Daftar_Aset_Tetap!A10) | B24: =IF(Daftar_Aset_Tetap!A10="","",Daftar_Aset_Tetap!B10) | C24: =IF(Daftar_Aset_Tetap!A10="","",Daftar_Aset_Tetap!G10) | D24: =IF(Daftar_Aset_Tetap!A10="","",Daftar_Aset_Tetap!H10)
A25: =IF(Daftar_Aset_Tetap!A11="","",Daftar_Aset_Tetap!A11) | B25: =IF(Daftar_Aset_Tetap!A11="","",Daftar_Aset_Tetap!B11) | C25: =IF(Daftar_Aset_Tetap!A11="","",Daftar_Aset_Tetap!G11) | D25: =IF(Daftar_Aset_Tetap!A11="","",Daftar_Aset_Tetap!H11)
A26: =IF(Daftar_Aset_Tetap!A12="","",Daftar_Aset_Tetap!A12) | B26: =IF(Daftar_Aset_Tetap!A12="","",Daftar_Aset_Tetap!B12) | C26: =IF(Daftar_Aset_Tetap!A12="","",Daftar_Aset_Tetap!G12) | D26: =IF(Daftar_Aset_Tetap!A12="","",Daftar_Aset_Tetap!H12)
A27: =IF(Daftar_Aset_Tetap!A13="","",Daftar_Aset_Tetap!A13) | B27: =IF(Daftar_Aset_Tetap!A13="","",Daftar_Aset_Tetap!B13) | C27: =IF(Daftar_Aset_Tetap!A13="","",Daftar_Aset_Tetap!G13) | D27: =IF(Daftar_Aset_Tetap!A13="","",Daftar_Aset_Tetap!H13)
A28: =IF(Daftar_Aset_Tetap!A14="","",Daftar_Aset_Tetap!A14) | B28: =IF(Daftar_Aset_Tetap!A14="","",Daftar_Aset_Tetap!B14) | C28: =IF(Daftar_Aset_Tetap!A14="","",Daftar_Aset_Tetap!G14) | D28: =IF(Daftar_Aset_Tetap!A14="","",Daftar_Aset_Tetap!H14)
A29: (b) Inventori | B29: Pada kos, atau kos/nilai boleh direalisasi bersih (mana lebih rendah). [ISI jika berbeza] ◄ ISI
A30: (c) Hutang ragu/lapuk | B30: [ISI polisi — cth. GP23 wajibkan ini bagi pinjaman >6 bulan tak berbayar] ◄ ISI
A31: (d) Pengiktirafan hasil | B31: [ISI — bagaimana setiap aktiviti mengiktiraf pendapatan] ◄ ISI
A32: (e) Usaha berterusan | B32: Disediakan berasaskan usaha berterusan. [ISI "TIDAK" + sebab jika tidak lagi benar] ◄ ISI
A34: NOTA 5 — POLISI RISIKO PENGURUSAN KEWANGAN (GP23 Lampiran 5 perenggan 6)
A35: (a) Risiko Kecairan: [ISI] ◄ ISI
A36: (b) Risiko Kredit: [ISI] ◄ ISI
A38: NOTA 6 — HARTA TANAH, LOJI DAN PERALATAN (PPE) (GP23 perenggan 15(a))
A39: Berkaitan untuk koperasi ini? | B39: [ISI — Ya/Tidak] ◄ ISI
A40: Kod Akaun — Kos PPE | B40: [ISI kod akaun] ◄ ISI
A41: Kod Akaun — Susut Nilai Terkumpul | B41: [ISI kod akaun] ◄ ISI
A42: Baki awal tahun (Sejarah_Baki jika ada) | B42: =IF($B$40="","",IFERROR(SUMIF(Sejarah_Baki!$B:$B,$B$40,Sejarah_Baki!$D:$D)-SUMIF(Sejarah_Baki!$B:$B,$B$40,Sejarah_Baki!$E:$E),"[ISI—thn pertama]")) -> 0
A43: Tambahan tahun semasa | B43: =IF($B$40="",0,SUMIFS(Baris_Transaksi!$D:$D,Baris_Transaksi!$C:$C,$B$40,Baris_Transaksi!$B:$B,"<>"&Tetapan!$C$18)) -> 0
A44: Pengurangan tahun semasa | B44: =IF($B$40="",0,SUMIFS(Baris_Transaksi!$E:$E,Baris_Transaksi!$C:$C,$B$40,Baris_Transaksi!$B:$B,"<>"&Tetapan!$C$18)) -> 0
A45: Baki akhir tahun (semakan bebas) | B45: =IF($B$40="",0,SUMIF(Imbangan_Duga!$A:$A,$B$40,Imbangan_Duga!$H:$H)) -> 0
A46: Susut Nilai Terkumpul (semakan bebas) | B46: =IF($B$41="",0,SUMIF(Imbangan_Duga!$A:$A,$B$41,Imbangan_Duga!$H:$H)) -> 0
...

Sheet Tetapan
A1: Label | B1: Nilai Ditetapkan | C1: Nilai Digunakan | E1: Skeleton only — this workbook ships with no cooperative-specific values. Row numbers match APZacct's real Tetapan layout so Nota's formulas resolve once imported alongside your real Tetapan.
A6: No. Pendaftaran SKM
A18: ID Transaksi Baki Pembukaan

Sheet Imbangan_Duga
A1: Skeleton only — empty on purpose. In your real APZacct sheet this is formula-driven per account; Nota's formulas SUMIF straight off column A/H here.
A4: Kod Akaun | H4: Baki Bersih (bertanda)

Sheet Baris_Transaksi
A1: Skeleton only — empty on purpose. This is your real ledger lines sheet once imported.
A4: ID | B4: ID Transaksi | C4: Kod Akaun | D4: Debit | E4: Kredit | F4: Memo

Sheet Sejarah_Baki
A1: Tahun (baki ditutup) | B1: Kod Akaun | C1: Nama Akaun | D1: Debit | E1: Kredit
A2: (dicipta automatik oleh posBakiPembukaan() selepas tahun pertama — kosong sehingga itu)

Sheet Daftar_Aset_Tetap
A1: Skeleton only — columns A/B/G/H/J are what Nota's Note 4 and Note 6 read.
A4: Nama Aset | B4: Kategori | C4: Kos Asal | D4: Tarikh Beli | E4: Jangka Hayat | F4: Nilai Baki | G4: Kaedah | H4: Kadar | I4: Susut Nilai Terkumpul | J4: Susut Nilai Tahun Ini | K4: Nilai Buku Bersih
